Workbook

Sheet 👋
B2: Odatlar planneri-dan foydalanishni boshlash uchun - quyidagi qo'llanma bilan tanishib chiqing Agar plannerdan foydalanishda biror savollaringiz mavjud bo'lsa - telegram orqali bog'laning
B6: Qo'llanma
B7: 1. Planner joylashgan sahifani oching (siz hozirda shu yerdasiz)
B8: 2. Tepa chap tomondagi "Fayl" tugmasiga bosing
B9: 3. Ochilgan oyna menyudan "создать копию" tugmasiga bosing
B10: 4. Sizda yangi oyna ochiladi va u yerda Odatlar planneri'dan foydalanishni boshlasangiz bo'ladi
B13: Biz bilan - yangi marralarga erishing va hayotingizni rejalashtiring!

Sheet Yillik maqsadlar
C3: ⟡ | D3: Yillik maqsadlar | N3: ⟡ | P3: Maqsadlar soni | U3: Bajarilgan maqsadlar soni
P4: =counta(C10:G17,C22:G29,C34:G41,C46:G53,AB46:AF53,AB34:AF41,AB22:AF29,AB10:AF17) -> 0 | U4: =sum(COUNTIF(B10:B17,TRUE),COUNTIF(B22:B29,TRUE),COUNTIF(B34:B41,TRUE),COUNTIF(B46:B53,TRUE),COUNTIF(AA10:AA17,TRUE),COUNTIF(AA22:AA29,TRUE),COUNTIF(AA34:AA41,TRUE),COUNTIF(AA46:AA53,TRUE)) -> 0
B7: Ish bo'yicha maqsadlar | AA7: Moliyaviy maqsadlar
B9: Maqsad | H9: Kundalik vazifa | N9: Haftalik vazifa | T9: Oylik vazifa | AA9: Maqsad | AG9: Kundalik vazifa | AM9: Haftalik vazifa | AS9: Oylik vazifa
B10: FALSE | AA10: FALSE
B11: FALSE | AA11: FALSE
B12: FALSE | AA12: FALSE
B13: FALSE | AA13: FALSE
B14: FALSE | AA14: FALSE
B15: FALSE | AA15: FALSE
B16: FALSE | AA16: FALSE
B17: FALSE | AA17: FALSE
B19: Ijodiy maqsadlar | AA19: Shaxsiy rivojlanish maqsadlari
B21: Maqsad | H21: Kundalik vazifa | N21: Haftalik vazifa | T21: Oylik vazifa | AA21: Maqsad | AG21: Kundalik vazifa | AM21: Haftalik vazifa | AS21: Oylik vazifa
B22: FALSE | AA22: FALSE
B23: FALSE | AA23: FALSE
B24: FALSE | AA24: FALSE
B25: FALSE | AA25: FALSE
B26: FALSE | AA26: FALSE
B27: FALSE | AA27: FALSE
B28: FALSE | AA28: FALSE
B29: FALSE | AA29: FALSE
B31: Munosabatlar bo'yicha maqsadlar | AA31: Ruhiy maqsadlar
B33: Maqsad | H33: Kundalik vazifa | N33: Haftalik vazifa | T33: Oylik vazifa | AA33: Maqsad | AG33: Kundalik vazifa | AM33: Haftalik vazifa | AS33: Oylik vazifa
B34: FALSE | AA34: FALSE
B35: FALSE | AA35: FALSE
B36: FALSE | AA36: FALSE
B37: FALSE | AA37: FALSE
B38: FALSE | AA38: FALSE
B39: FALSE | AA39: FALSE
B40: FALSE | AA40: FALSE
B41: FALSE | AA41: FALSE
B43: Boshqa maqsadlar | AA43: Boshqa maqsadlar
B45: Maqsad | H45: Kundalik vazifa | N45: Haftalik vazifa | T45: Oylik vazifa | AA45: Maqsad | AG45: Kundalik vazifa | AM45: Haftalik vazifa | AS45: Oylik vazifa
B46: FALSE | AA46: FALSE
B47: FALSE | AA47: FALSE
B48: FALSE | AA48: FALSE
B49: FALSE | AA49: FALSE
B50: FALSE | AA50: FALSE
B51: FALSE | AA51: FALSE
...

Sheet Dashboard
B3: ⟡ | C3: Dashboard | F3: ⟡ | P3: YIL | Q3: 2025
B9: месяца | C9: Progres %
B10: Yanvar | C10: =D29 -> 0.068010076
B11: Fevral | C11: =J29 -> 0
B12: Mart | C12: =P29 -> 0
B13: Aprel | C13: =D39 -> 0
B14: May | C14: =J39 -> 0
B15: Iyun | C15: =P39 -> 0
B16: Iyul | C16: =D49 -> 0
B17: Avgust | C17: =J49 -> 0
B18: Sentabr | C18: =P49 -> 0
B19: Oktabr | C19: =D59 -> 0
B20: Noyabr | C20: =J59 -> 0
B21: Dekabr | C21: =P59 -> 0
B23: Yanvar | H23: Fevral | N23: Mart
B25: Odatlar soni | D25: =Yan!$I$4 -> 0 | H25: Odatlar soni | J25: =Fev!$I$4 -> 0 | N25: Odatlar soni | P25: =Mart!$I$4 -> 0
B27: Bajarilgan | D27: =Yan!$O$4 -> 27 | H27: Bajarilgan | J27: =Fev!$O$4 -> 0 | N27: Bajarilgan | P27: =Mart!$O$4 -> 0
B29: Progres % | D29: =Yan!$AB$4 -> 0.068010076 | H29: Progres % | J29: =Fev!$AB$4 -> 0 | N29: Progres % | P29: =Mart!$AB$4 -> 0
B33: Aprel | H33: May | N33: Iyun
B35: Odatlar soni | D35: =Apr!$I$4 -> 0 | H35: Odatlar soni | J35: =May!$I$4 -> 0 | N35: Odatlar soni | P35: =Iyun!$I$4 -> 0
B37: Bajarilgan | D37: =Apr!$O$4 -> 0 | H37: Bajarilgan | J37: =May!$O$4 -> 0 | N37: Bajarilgan | P37: =Iyun!$O$4 -> 0
B39: Progres % | D39: =Apr!$AB$4 -> 0 | H39: Progres % | J39: =May!$AB$4 -> 0 | N39: Progres % | P39: =Iyun!$AB$4 -> 0
B43: Iyul | H43: Avgust | N43: Sentabr
B45: Odatlar soni | D45: =Iyul!$I$4 -> 0 | H45: Odatlar soni | J45: =Avg!$I$4 -> 0 | N45: Odatlar soni | P45: =Sen!$I$4 -> 0
B47: Bajarilgan | D47: =Iyul!$O$4 -> 0 | H47: Bajarilgan | J47: =Avg!$O$4 -> 0 | N47: Bajarilgan | P47: =Sen!$O$4 -> 0
B49: Progres % | D49: =Iyul!$AB$4 -> 0 | H49: Progres % | J49: =Avg!$AB$4 -> 0 | N49: Progres % | P49: =Sen!$AB$4 -> 0
B53: Oktabr | H53: Noyabr | N53: Dekabr
B55: Odatlar soni | D55: =Okt!$I$4 -> 0 | H55: Odatlar soni | J55: =Noy!$I$4 -> 0 | N55: Odatlar soni | P55: =Dek!$I$4 -> 0
B57: Bajarilgan | D57: =Okt!$O$4 -> 0 | H57: Bajarilgan | J57: =Noy!$O$4 -> 0 | N57: Bajarilgan | P57: =Dek!$O$4 -> 0
B59: Progres % | D59: =Okt!$AB$4 -> 0 | H59: Progres % | J59: =Noy!$AB$4 -> 0 | N59: Progres % | P59: =Dek!$AB$4 -> 0

Sheet Yan
B3: Yanvar | I3: Odatlar soni | O3: Bajarilgan odatlar soni | V3: Oylik Progres | AB3: Progres %
I4: =SUM(countA($B$10:$B$21),$I$62) -> 0 | O4: =SUM(COUNTIF($C$10:$AG$21, true),$J$62) -> 27 | V4: =IFERROR(__xludf.DUMMYFUNCTION("iferror(SPARKLINE($AB$4:$AF$4,{""charttype"",""bar"";""max"",1;""color1"",""#c9e4b2""}))"),"") | AB4: =$O$4/SUM(COUNTA($C$10:$AG$21),$K$62) -> 0.068010076
B7: Kundalik vazifalar | C7: Hafta 1 | J7: Hafta 2 | Q7: Hafta 3 | X7: Hafta 4 | AI7: Analiz | AK7: Progres
C8: =weekday(date(Dashboard!$Q$3,$AG$45,C9),1) -> 4 | D8: =weekday(date(Dashboard!$Q$3,$AG$45,D9),1) -> 5 | E8: =weekday(date(Dashboard!$Q$3,$AG$45,E9),1) -> 6 | F8: =weekday(date(Dashboard!$Q$3,$AG$45,F9),1) -> 7 | G8: =weekday(date(Dashboard!$Q$3,$AG$45,G9),1) -> 1 | H8: =weekday(date(Dashboard!$Q$3,$AG$45,H9),1) -> 2 | I8: =weekday(date(Dashboard!$Q$3,$AG$45,I9),1) -> 3 | J8: =weekday(date(Dashboard!$Q$3,$AG$45,J9),1) -> 4 | ... AG8: =weekday(date(Dashboard!$Q$3,$AG$45,AG9),1) -> 6
B9: =TODAY() -> 46025 | C9: 1 | D9: 2 | E9: 3 | F9: 4 | G9: 5 | H9: 6 | I9: 7 | J9: 8 | K9: 9 | L9: 10 | M9: 11 | N9: 12 | O9: 13 | P9: 14 | Q9: 15 | R9: 16 | S9: 17 | T9: 18 | U9: 19 | V9: 20 | W9: 21 | X9: 22 | Y9: 23 | Z9: 24 | AA9: 25 | AB9: 26 | AC9: 27 | AD9: 28 | AE9: 29 | AF9: 30 | AG9: 31 | AI9: Maqsad | AJ9: Jami
C10: TRUE | D10: TRUE | E10: TRUE | F10: TRUE | G10: TRUE | H10: TRUE | I10: FALSE | J10: TRUE | K10: TRUE | L10: TRUE | M10: FALSE | N10: FALSE | O10: FALSE | P10: FALSE | Q10: FALSE | R10: FALSE | S10: FALSE | T10: FALSE | U10: FALSE | V10: FALSE | W10: FALSE | X10: FALSE | Y10: FALSE | Z10: FALSE | AA10: FALSE | AB10: TRUE | AC10: TRUE | AD10: FALSE | AE10: FALSE | AF10: FALSE | AG10: FALSE | AJ10: {=MMULT(N($C$10:$AG$21), TRANSPOSE(COLUMN($C$10:$AG$21)^0))} -> 11 | AK10: =IFERROR(__xludf.DUMMYFUNCTION("iferror(SPARKLINE(AJ10/AI10,{""charttype"",""bar"";""max"",1;""color1"",""#c9e4b2""}))"),"")
C11: FALSE | D11: FALSE | E11: FALSE | F11: FALSE | G11: FALSE | H11: FALSE | I11: FALSE | J11: FALSE | K11: FALSE | L11: FALSE | M11: FALSE | N11: FALSE | O11: FALSE | P11: FALSE | Q11: FALSE | R11: FALSE | S11: FALSE | T11: FALSE | U11: FALSE | V11: FALSE | W11: FALSE | X11: FALSE | Y11: FALSE | Z11: FALSE | AA11: FALSE | AB11: TRUE | AC11: FALSE | AD11: FALSE | AE11: FALSE | AF11: FALSE | AG11: FALSE | AJ11: 1 | AK11: =IFERROR(__xludf.DUMMYFUNCTION("iferror(SPARKLINE(AJ11/AI11,{""charttype"",""bar"";""max"",1;""color1"",""#c9e4b2""}))"),"")
C12: FALSE | D12: FALSE | E12: FALSE | F12: FALSE | G12: FALSE | H12: FALSE | I12: FALSE | J12: FALSE | K12: FALSE | L12: FALSE | M12: FALSE | N12: FALSE | O12: FALSE | P12: FALSE | Q12: FALSE | R12: FALSE | S12: FALSE | T12: FALSE | U12: TRUE | V12: FALSE | W12: FALSE | X12: FALSE | Y12: FALSE | Z12: FALSE | AA12: FALSE | AB12: TRUE | AC12: FALSE | AD12: FALSE | AE12: FALSE | AF12: FALSE | AG12: FALSE | AJ12: 2 | AK12: =IFERROR(__xludf.DUMMYFUNCTION("iferror(SPARKLINE(AJ12/AI12,{""charttype"",""bar"";""max"",1;""color1"",""#c9e4b2""}))"),"")
C13: FALSE | D13: FALSE | E13: FALSE | F13: FALSE | G13: FALSE | H13: FALSE | I13: FALSE | J13: FALSE | K13: FALSE | L13: FALSE | M13: FALSE | N13: TRUE | O13: FALSE | P13: FALSE | Q13: FALSE | R13: TRUE | S13: FALSE | T13: TRUE | U13: FALSE | V13: FALSE | W13: FALSE | X13: TRUE | Y13: FALSE | Z13: FALSE | AA13: TRUE | AB13: FALSE | AC13: FALSE | AD13: FALSE | AE13: FALSE | AF13: FALSE | AG13: FALSE | AJ13: 5 | AK13: =IFERROR(__xludf.DUMMYFUNCTION("iferror(SPARKLINE(AJ13/AI13,{""charttype"",""bar"";""max"",1;""color1"",""#c9e4b2""}))"),"")
C14: FALSE | D14: FALSE | E14: FALSE | F14: FALSE | G14: FALSE | H14: FALSE | I14: FALSE | J14: FALSE | K14: FALSE | L14: FALSE | M14: FALSE | N14: FALSE | O14: FALSE | P14: FALSE | Q14: TRUE | R14: FALSE | S14: FALSE | T14: FALSE | U14: FALSE | V14: TRUE | W14: FALSE | X14: FALSE | Y14: FALSE | Z14: TRUE | AA14: FALSE | AB14: FALSE | AC14: FALSE | AD14: FALSE | AE14: FALSE | AF14: FALSE | AG14: FALSE | AJ14: 3 | AK14: =IFERROR(__xludf.DUMMYFUNCTION("iferror(SPARKLINE(AJ14/AI14,{""charttype"",""bar"";""max"",1;""color1"",""#c9e4b2""}))"),"")
C15: FALSE | D15: FALSE | E15: FALSE | F15: FALSE | G15: FALSE | H15: FALSE | I15: FALSE | J15: FALSE | K15: FALSE | L15: FALSE | M15: FALSE | N15: FALSE | O15: FALSE | P15: FALSE | Q15: FALSE | R15: FALSE | S15: FALSE | T15: FALSE | U15: FALSE | V15: TRUE | W15: FALSE | X15: FALSE | Y15: FALSE | Z15: FALSE | AA15: FALSE | AB15: FALSE | AC15: FALSE | AD15: FALSE | AE15: FALSE | AF15: FALSE | AG15: FALSE | AJ15: 1 | AK15: =IFERROR(__xludf.DUMMYFUNCTION("iferror(SPARKLINE(AJ15/AI15,{""charttype"",""bar"";""max"",1;""color1"",""#c9e4b2""}))"),"")
C16: FALSE | D16: FALSE | E16: FALSE | F16: FALSE | G16: FALSE | H16: FALSE | I16: FALSE | J16: FALSE | K16: FALSE | L16: FALSE | M16: FALSE | N16: FALSE | O16: FALSE | P16: FALSE | Q16: FALSE | R16: FALSE | S16: FALSE | T16: FALSE | U16: FALSE | V16: TRUE | W16: FALSE | X16: FALSE | Y16: FALSE | Z16: FALSE | AA16: FALSE | AB16: FALSE | AC16: FALSE | AD16: FALSE | AE16: FALSE | AF16: FALSE | AG16: FALSE | AJ16: 1 | AK16: =IFERROR(__xludf.DUMMYFUNCTION("iferror(SPARKLINE(AJ16/AI16,{""charttype"",""bar"";""max"",1;""color1"",""#c9e4b2""}))"),"")
C17: FALSE | D17: FALSE | E17: FALSE | F17: FALSE | G17: FALSE | H17: FALSE | I17: FALSE | J17: FALSE | K17: FALSE | L17: FALSE | M17: FALSE | N17: FALSE | O17: FALSE | P17: FALSE | Q17: FALSE | R17: FALSE | S17: FALSE | T17: FALSE | U17: FALSE | V17: TRUE | W17: FALSE | X17: FALSE | Y17: FALSE | Z17: FALSE | AA17: FALSE | AB17: FALSE | AC17: FALSE | AD17: FALSE | AE17: FALSE | AF17: FALSE | AG17: FALSE | AJ17: 1 | AK17: =IFERROR(__xludf.DUMMYFUNCTION("iferror(SPARKLINE(AJ17/AI17,{""charttype"",""bar"";""max"",1;""color1"",""#c9e4b2""}))"),"")
C18: FALSE | D18: FALSE | E18: FALSE | F18: FALSE | G18: FALSE | H18: FALSE | I18: FALSE | J18: FALSE | K18: FALSE | L18: FALSE | M18: FALSE | N18: FALSE | O18: FALSE | P18: FALSE | Q18: FALSE | R18: FALSE | S18: FALSE | T18: FALSE | U18: FALSE | V18: TRUE | W18: FALSE | X18: FALSE | Y18: FALSE | Z18: FALSE | AA18: FALSE | AB18: FALSE | AC18: FALSE | AD18: FALSE | AE18: FALSE | AF18: FALSE | AG18: FALSE | AJ18: 1 | AK18: =IFERROR(__xludf.DUMMYFUNCTION("iferror(SPARKLINE(AJ18/AI18,{""charttype"",""bar"";""max"",1;""color1"",""#c9e4b2""}))"),"")
C19: FALSE | D19: FALSE | E19: FALSE | F19: FALSE | G19: FALSE | H19: FALSE | I19: FALSE | J19: FALSE | K19: FALSE | L19: FALSE | M19: FALSE | N19: FALSE | O19: FALSE | P19: FALSE | Q19: FALSE | R19: FALSE | S19: FALSE | T19: FALSE | U19: FALSE | V19: TRUE | W19: FALSE | X19: FALSE | Y19: FALSE | Z19: FALSE | AA19: FALSE | AB19: FALSE | AC19: FALSE | AD19: FALSE | AE19: FALSE | AF19: FALSE | AG19: FALSE | AJ19: 1 | AK19: =IFERROR(__xludf.DUMMYFUNCTION("iferror(SPARKLINE(AJ19/AI19,{""charttype"",""bar"";""max"",1;""color1"",""#c9e4b2""}))"),"")
C20: FALSE | D20: FALSE | E20: FALSE | F20: FALSE | G20: FALSE | H20: FALSE | I20: FALSE | J20: FALSE | K20: FALSE | L20: FALSE | M20: FALSE | N20: FALSE | O20: FALSE | P20: FALSE | Q20: FALSE | R20: FALSE | S20: FALSE | T20: FALSE | U20: FALSE | V20: FALSE | W20: FALSE | X20: FALSE | Y20: FALSE | Z20: FALSE | AA20: FALSE | AB20: FALSE | AC20: FALSE | AD20: FALSE | AE20: FALSE | AF20: FALSE | AG20: FALSE | AJ20: 0 | AK20: =IFERROR(__xludf.DUMMYFUNCTION("iferror(SPARKLINE(AJ20/AI20,{""charttype"",""bar"";""max"",1;""color1"",""#c9e4b2""}))"),"")
C21: FALSE | D21: FALSE | E21: FALSE | F21: FALSE | G21: FALSE | H21: FALSE | I21: FALSE | J21: FALSE | K21: FALSE | L21: FALSE | M21: FALSE | N21: FALSE | O21: FALSE | P21: FALSE | Q21: FALSE | R21: FALSE | S21: FALSE | T21: FALSE | U21: FALSE | V21: FALSE | W21: FALSE | X21: FALSE | Y21: FALSE | Z21: FALSE | AA21: FALSE | AB21: FALSE | AC21: FALSE | AD21: FALSE | AE21: FALSE | AF21: FALSE | AG21: FALSE | AJ21: 0 | AK21: =IFERROR(__xludf.DUMMYFUNCTION("iferror(SPARKLINE(AJ21/AI21,{""charttype"",""bar"";""max"",1;""color1"",""#c9e4b2""}))"),"")
B23: Progres % | C23: =COUNTIF(C10:C21, TRUE)/COUNTA(C10:C21) -> 0.083333333 | D23: =COUNTIF(D10:D21, TRUE)/COUNTA(D10:D21) -> 0.083333333 | E23: =COUNTIF(E10:E21, TRUE)/COUNTA(E10:E21) -> 0.083333333 | F23: =COUNTIF(F10:F21, TRUE)/COUNTA(F10:F21) -> 0.083333333 | G23: =COUNTIF(G10:G21, TRUE)/COUNTA(G10:G21) -> 0.083333333 | H23: =COUNTIF(H10:H21, TRUE)/COUNTA(H10:H21) -> 0.083333333 | I23: =COUNTIF(I10:I21, TRUE)/COUNTA(I10:I21) -> 0 | J23: =COUNTIF(J10:J21, TRUE)/COUNTA(J10:J21) -> 0.083333333 | ... AG23: =COUNTIF(AG10:AG21, TRUE)/COUNTA(AG10:AG21) -> 0
B24: To'ldirilgan | C24: =COUNTIF(C10:C21, true) -> 1 | D24: =COUNTIF(D10:D21, true) -> 1 | E24: =COUNTIF(E10:E21, true) -> 1 | F24: =COUNTIF(F10:F21, true) -> 1 | G24: =COUNTIF(G10:G21, true) -> 1 | H24: =COUNTIF(H10:H21, true) -> 1 | I24: =COUNTIF(I10:I21, true) -> 0 | J24: =COUNTIF(J10:J21, true) -> 1 | ... AG24: =COUNTIF(AG10:AG21, true) -> 0
B25: To'ldirilmagan | C25: =COUNTIF(C10:C21, false) -> 11 | D25: =COUNTIF(D10:D21, false) -> 11 | E25: =COUNTIF(E10:E21, false) -> 11 | F25: =COUNTIF(F10:F21, false) -> 11 | G25: =COUNTIF(G10:G21, false) -> 11 | H25: =COUNTIF(H10:H21, false) -> 11 | I25: =COUNTIF(I10:I21, false) -> 12 | J25: =COUNTIF(J10:J21, false) -> 11 | ... AG25: =COUNTIF(AG10:AG21, false) -> 12
B36: Kundalik holat | AI36: O'rtacha qiymat
B37: Kayfiyat | AI37: =iferror(Average(C37:AG37), "")
B38: Energiya | AI38: =iferror(Average(C38:AG38), "")
B39: Motivatsyia | AI39: =iferror(Average(C39:AG39), "")
B42: Haftalik | C42: Hafta 1 | J42: Hafta 2 | Q42: Hafta 3 | X42: Hafta 4
I43: FALSE | P43: FALSE | W43: FALSE | AD43: FALSE
I44: FALSE | P44: FALSE | W44: FALSE | AD44: FALSE | AG44: January
I45: FALSE | P45: FALSE | W45: FALSE | AD45: FALSE | AG45: 1
I46: FALSE | P46: FALSE | W46: FALSE | AD46: FALSE
I47: FALSE | P47: FALSE | W47: FALSE | AD47: FALSE
B49: Haftalik fikrlar
B54: Oylik | C54: Ushbu oy maqsadlari
P55: FALSE
P56: FALSE
P57: FALSE
P58: FALSE
P59: FALSE
B62: =COUNTIF($I$43:$I$47, true) -> 0 | C62: {=$C$43:$H$47} | I62: {=COUNTA(UNIQUE($C$62:$C$140))} -> 0 | J62: =sum($B$62,$B$78,$B$110,$B$126) -> 0 | K62: =sum(COUNTA($I$43:$I$47),COUNTA($P$43:$P$47),COUNTA($W$43:$W$47),COUNTA($AD$43:$AD$47),COUNTA($P$55:$P$59)) -> 25
B78: =COUNTIF($P$43:$P$47, true) -> 0 | C78: {=$J$43:$O$47}
B94: =COUNTIF($W$43:$W$47, true) -> 0 | C94: {=$Q$43:$V$47}
...

Sheet Fev
B3: Fevral | I3: Odatlar soni | O3: Bajarilgan odatlar soni | V3: Oylik Progres | AB3: Progres %
I4: =SUM(countA($B$10:$B$21),$I$62) -> 0 | O4: =SUM(COUNTIF($C$10:$AG$21, true),$J$62) -> 0 | V4: =IFERROR(__xludf.DUMMYFUNCTION("iferror(SPARKLINE($AB$4:$AF$4,{""charttype"",""bar"";""max"",1;""color1"",""#c9e4b2""}))"),"") | AB4: =$O$4/SUM(COUNTA($C$10:$AG$21),$K$62) -> 0
B7: Kundalik vazifalar | C7: Hafta 1 | J7: Hafta 2 | Q7: Hafta 3 | X7: Hafta 4 | AI7: Analiz | AK7: Progres
C8: =weekday(date(Dashboard!$Q$3,$AG$45,C9),1) -> 7 | D8: =weekday(date(Dashboard!$Q$3,$AG$45,D9),1) -> 1 | E8: =weekday(date(Dashboard!$Q$3,$AG$45,E9),1) -> 2 | F8: =weekday(date(Dashboard!$Q$3,$AG$45,F9),1) -> 3 | G8: =weekday(date(Dashboard!$Q$3,$AG$45,G9),1) -> 4 | H8: =weekday(date(Dashboard!$Q$3,$AG$45,H9),1) -> 5 | I8: =weekday(date(Dashboard!$Q$3,$AG$45,I9),1) -> 6 | J8: =weekday(date(Dashboard!$Q$3,$AG$45,J9),1) -> 7 | ... AG8: =weekday(date(Dashboard!$Q$3,$AG$45,AG9),1) -> 2
B9: =TODAY() -> 46025 | C9: 1 | D9: 2 | E9: 3 | F9: 4 | G9: 5 | H9: 6 | I9: 7 | J9: 8 | K9: 9 | L9: 10 | M9: 11 | N9: 12 | O9: 13 | P9: 14 | Q9: 15 | R9: 16 | S9: 17 | T9: 18 | U9: 19 | V9: 20 | W9: 21 | X9: 22 | Y9: 23 | Z9: 24 | AA9: 25 | AB9: 26 | AC9: 27 | AD9: 28 | AE9: 29 | AF9: 30 | AG9: 31 | AI9: Maqsad | AJ9: Jami
C10: FALSE | D10: FALSE | E10: FALSE | F10: FALSE | G10: FALSE | H10: FALSE | I10: FALSE | J10: FALSE | K10: FALSE | L10: FALSE | M10: FALSE | N10: FALSE | O10: FALSE | P10: FALSE | Q10: FALSE | R10: FALSE | S10: FALSE | T10: FALSE | U10: FALSE | V10: FALSE | W10: FALSE | X10: FALSE | Y10: FALSE | Z10: FALSE | AA10: FALSE | AB10: FALSE | AC10: FALSE | AD10: FALSE | AE10: FALSE | AF10: FALSE | AG10: FALSE | AJ10: {=MMULT(N($C$10:$AG$21), TRANSPOSE(COLUMN($C$10:$AG$21)^0))} -> 0 | AK10: =IFERROR(__xludf.DUMMYFUNCTION("iferror(SPARKLINE(AJ10/AI10,{""charttype"",""bar"";""max"",1;""color1"",""#c9e4b2""}))"),"")
C11: FALSE | D11: FALSE | E11: FALSE | F11: FALSE | G11: FALSE | H11: FALSE | I11: FALSE | J11: FALSE | K11: FALSE | L11: FALSE | M11: FALSE | N11: FALSE | O11: FALSE | P11: FALSE | Q11: FALSE | R11: FALSE | S11: FALSE | T11: FALSE | U11: FALSE | V11: FALSE | W11: FALSE | X11: FALSE | Y11: FALSE | Z11: FALSE | AA11: FALSE | AB11: FALSE | AC11: FALSE | AD11: FALSE | AE11: FALSE | AF11: FALSE | AG11: FALSE | AJ11: 0 | AK11: =IFERROR(__xludf.DUMMYFUNCTION("iferror(SPARKLINE(AJ11/AI11,{""charttype"",""bar"";""max"",1;""color1"",""#c9e4b2""}))"),"")
C12: FALSE | D12: FALSE | E12: FALSE | F12: FALSE | G12: FALSE | H12: FALSE | I12: FALSE | J12: FALSE | K12: FALSE | L12: FALSE | M12: FALSE | N12: FALSE | O12: FALSE | P12: FALSE | Q12: FALSE | R12: FALSE | S12: FALSE | T12: FALSE | U12: FALSE | V12: FALSE | W12: FALSE | X12: FALSE | Y12: FALSE | Z12: FALSE | AA12: FALSE | AB12: FALSE | AC12: FALSE | AD12: FALSE | AE12: FALSE | AF12: FALSE | AG12: FALSE | AJ12: 0 | AK12: =IFERROR(__xludf.DUMMYFUNCTION("iferror(SPARKLINE(AJ12/AI12,{""charttype"",""bar"";""max"",1;""color1"",""#c9e4b2""}))"),"")
C13: FALSE | D13: FALSE | E13: FALSE | F13: FALSE | G13: FALSE | H13: FALSE | I13: FALSE | J13: FALSE | K13: FALSE | L13: FALSE | M13: FALSE | N13: FALSE | O13: FALSE | P13: FALSE | Q13: FALSE | R13: FALSE | S13: FALSE | T13: FALSE | U13: FALSE | V13: FALSE | W13: FALSE | X13: FALSE | Y13: FALSE | Z13: FALSE | AA13: FALSE | AB13: FALSE | AC13: FALSE | AD13: FALSE | AE13: FALSE | AF13: FALSE | AG13: FALSE | AJ13: 0 | AK13: =IFERROR(__xludf.DUMMYFUNCTION("iferror(SPARKLINE(AJ13/AI13,{""charttype"",""bar"";""max"",1;""color1"",""#c9e4b2""}))"),"")
C14: FALSE | D14: FALSE | E14: FALSE | F14: FALSE | G14: FALSE | H14: FALSE | I14: FALSE | J14: FALSE | K14: FALSE | L14: FALSE | M14: FALSE | N14: FALSE | O14: FALSE | P14: FALSE | Q14: FALSE | R14: FALSE | S14: FALSE | T14: FALSE | U14: FALSE | V14: FALSE | W14: FALSE | X14: FALSE | Y14: FALSE | Z14: FALSE | AA14: FALSE | AB14: FALSE | AC14: FALSE | AD14: FALSE | AE14: FALSE | AF14: FALSE | AG14: FALSE | AJ14: 0 | AK14: =IFERROR(__xludf.DUMMYFUNCTION("iferror(SPARKLINE(AJ14/AI14,{""charttype"",""bar"";""max"",1;""color1"",""#c9e4b2""}))"),"")
C15: FALSE | D15: FALSE | E15: FALSE | F15: FALSE | G15: FALSE | H15: FALSE | I15: FALSE | J15: FALSE | K15: FALSE | L15: FALSE | M15: FALSE | N15: FALSE | O15: FALSE | P15: FALSE | Q15: FALSE | R15: FALSE | S15: FALSE | T15: FALSE | U15: FALSE | V15: FALSE | W15: FALSE | X15: FALSE | Y15: FALSE | Z15: FALSE | AA15: FALSE | AB15: FALSE | AC15: FALSE | AD15: FALSE | AE15: FALSE | AF15: FALSE | AG15: FALSE | AJ15: 0 | AK15: =IFERROR(__xludf.DUMMYFUNCTION("iferror(SPARKLINE(AJ15/AI15,{""charttype"",""bar"";""max"",1;""color1"",""#c9e4b2""}))"),"")
C16: FALSE | D16: FALSE | E16: FALSE | F16: FALSE | G16: FALSE | H16: FALSE | I16: FALSE | J16: FALSE | K16: FALSE | L16: FALSE | M16: FALSE | N16: FALSE | O16: FALSE | P16: FALSE | Q16: FALSE | R16: FALSE | S16: FALSE | T16: FALSE | U16: FALSE | V16: FALSE | W16: FALSE | X16: FALSE | Y16: FALSE | Z16: FALSE | AA16: FALSE | AB16: FALSE | AC16: FALSE | AD16: FALSE | AE16: FALSE | AF16: FALSE | AG16: FALSE | AJ16: 0 | AK16: =IFERROR(__xludf.DUMMYFUNCTION("iferror(SPARKLINE(AJ16/AI16,{""charttype"",""bar"";""max"",1;""color1"",""#c9e4b2""}))"),"")
C17: FALSE | D17: FALSE | E17: FALSE | F17: FALSE | G17: FALSE | H17: FALSE | I17: FALSE | J17: FALSE | K17: FALSE | L17: FALSE | M17: FALSE | N17: FALSE | O17: FALSE | P17: FALSE | Q17: FALSE | R17: FALSE | S17: FALSE | T17: FALSE | U17: FALSE | V17: FALSE | W17: FALSE | X17: FALSE | Y17: FALSE | Z17: FALSE | AA17: FALSE | AB17: FALSE | AC17: FALSE | AD17: FALSE | AE17: FALSE | AF17: FALSE | AG17: FALSE | AJ17: 0 | AK17: =IFERROR(__xludf.DUMMYFUNCTION("iferror(SPARKLINE(AJ17/AI17,{""charttype"",""bar"";""max"",1;""color1"",""#c9e4b2""}))"),"")
C18: FALSE | D18: FALSE | E18: FALSE | F18: FALSE | G18: FALSE | H18: FALSE | I18: FALSE | J18: FALSE | K18: FALSE | L18: FALSE | M18: FALSE | N18: FALSE | O18: FALSE | P18: FALSE | Q18: FALSE | R18: FALSE | S18: FALSE | T18: FALSE | U18: FALSE | V18: FALSE | W18: FALSE | X18: FALSE | Y18: FALSE | Z18: FALSE | AA18: FALSE | AB18: FALSE | AC18: FALSE | AD18: FALSE | AE18: FALSE | AF18: FALSE | AG18: FALSE | AJ18: 0 | AK18: =IFERROR(__xludf.DUMMYFUNCTION("iferror(SPARKLINE(AJ18/AI18,{""charttype"",""bar"";""max"",1;""color1"",""#c9e4b2""}))"),"")
C19: FALSE | D19: FALSE | E19: FALSE | F19: FALSE | G19: FALSE | H19: FALSE | I19: FALSE | J19: FALSE | K19: FALSE | L19: FALSE | M19: FALSE | N19: FALSE | O19: FALSE | P19: FALSE | Q19: FALSE | R19: FALSE | S19: FALSE | T19: FALSE | U19: FALSE | V19: FALSE | W19: FALSE | X19: FALSE | Y19: FALSE | Z19: FALSE | AA19: FALSE | AB19: FALSE | AC19: FALSE | AD19: FALSE | AE19: FALSE | AF19: FALSE | AG19: FALSE | AJ19: 0 | AK19: =IFERROR(__xludf.DUMMYFUNCTION("iferror(SPARKLINE(AJ19/AI19,{""charttype"",""bar"";""max"",1;""color1"",""#c9e4b2""}))"),"")
C20: FALSE | D20: FALSE | E20: FALSE | F20: FALSE | G20: FALSE | H20: FALSE | I20: FALSE | J20: FALSE | K20: FALSE | L20: FALSE | M20: FALSE | N20: FALSE | O20: FALSE | P20: FALSE | Q20: FALSE | R20: FALSE | S20: FALSE | T20: FALSE | U20: FALSE | V20: FALSE | W20: FALSE | X20: FALSE | Y20: FALSE | Z20: FALSE | AA20: FALSE | AB20: FALSE | AC20: FALSE | AD20: FALSE | AE20: FALSE | AF20: FALSE | AG20: FALSE | AJ20: 0 | AK20: =IFERROR(__xludf.DUMMYFUNCTION("iferror(SPARKLINE(AJ20/AI20,{""charttype"",""bar"";""max"",1;""color1"",""#c9e4b2""}))"),"")
C21: FALSE | D21: FALSE | E21: FALSE | F21: FALSE | G21: FALSE | H21: FALSE | I21: FALSE | J21: FALSE | K21: FALSE | L21: FALSE | M21: FALSE | N21: FALSE | O21: FALSE | P21: FALSE | Q21: FALSE | R21: FALSE | S21: FALSE | T21: FALSE | U21: FALSE | V21: FALSE | W21: FALSE | X21: FALSE | Y21: FALSE | Z21: FALSE | AA21: FALSE | AB21: FALSE | AC21: FALSE | AD21: FALSE | AE21: FALSE | AF21: FALSE | AG21: FALSE | AJ21: 0 | AK21: =IFERROR(__xludf.DUMMYFUNCTION("iferror(SPARKLINE(AJ21/AI21,{""charttype"",""bar"";""max"",1;""color1"",""#c9e4b2""}))"),"")
B23: Progres % | C23: =COUNTIF(C10:C21, TRUE)/COUNTA(C10:C21) -> 0 | D23: =COUNTIF(D10:D21, TRUE)/COUNTA(D10:D21) -> 0 | E23: =COUNTIF(E10:E21, TRUE)/COUNTA(E10:E21) -> 0 | F23: =COUNTIF(F10:F21, TRUE)/COUNTA(F10:F21) -> 0 | G23: =COUNTIF(G10:G21, TRUE)/COUNTA(G10:G21) -> 0 | H23: =COUNTIF(H10:H21, TRUE)/COUNTA(H10:H21) -> 0 | I23: =COUNTIF(I10:I21, TRUE)/COUNTA(I10:I21) -> 0 | J23: =COUNTIF(J10:J21, TRUE)/COUNTA(J10:J21) -> 0 | ... AG23: =COUNTIF(AG10:AG21, TRUE)/COUNTA(AG10:AG21) -> 0
B24: To'ldirilgan | C24: =COUNTIF(C10:C21, true) -> 0 | D24: =COUNTIF(D10:D21, true) -> 0 | E24: =COUNTIF(E10:E21, true) -> 0 | F24: =COUNTIF(F10:F21, true) -> 0 | G24: =COUNTIF(G10:G21, true) -> 0 | H24: =COUNTIF(H10:H21, true) -> 0 | I24: =COUNTIF(I10:I21, true) -> 0 | J24: =COUNTIF(J10:J21, true) -> 0 | ... AG24: =COUNTIF(AG10:AG21, true) -> 0
B25: To'ldirilmagan | C25: =COUNTIF(C10:C21, false) -> 12 | D25: =COUNTIF(D10:D21, false) -> 12 | E25: =COUNTIF(E10:E21, false) -> 12 | F25: =COUNTIF(F10:F21, false) -> 12 | G25: =COUNTIF(G10:G21, false) -> 12 | H25: =COUNTIF(H10:H21, false) -> 12 | I25: =COUNTIF(I10:I21, false) -> 12 | J25: =COUNTIF(J10:J21, false) -> 12 | ... AG25: =COUNTIF(AG10:AG21, false) -> 12
B36: Kundalik holat | AI36: O'rtacha qiymat
B37: Kayfiyat | AI37: =iferror(Average(C37:AG37), "")
B38: Energiya | AI38: =iferror(Average(C38:AG38), "")
B39: Motivatsiya | AI39: =iferror(Average(C39:AG39), "")
B42: Haftalik | C42: Hafta 1 | J42: Hafta 2 | Q42: Hafta 3 | X42: Hafta 4
I43: FALSE | P43: FALSE | W43: FALSE | AD43: FALSE
I44: FALSE | P44: FALSE | W44: FALSE | AD44: FALSE | AG44: January
I45: FALSE | P45: FALSE | W45: FALSE | AD45: FALSE | AG45: 2
I46: FALSE | P46: FALSE | W46: FALSE | AD46: FALSE
I47: FALSE | P47: FALSE | W47: FALSE | AD47: FALSE
B49: Haftalik fikrlar
B54: Oylik | C54: Ushbu oy maqsadlari
P55: FALSE
P56: FALSE
P57: FALSE
P58: FALSE
P59: FALSE
B62: =COUNTIF($I$43:$I$47, true) -> 0 | C62: {=$C$43:$H$47} | I62: {=COUNTA(UNIQUE($C$62:$C$140))} -> 0 | J62: =sum($B$62,$B$78,$B$110,$B$126) -> 0 | K62: =sum(COUNTA($I$43:$I$47),COUNTA($P$43:$P$47),COUNTA($W$43:$W$47),COUNTA($AD$43:$AD$47),COUNTA($P$55:$P$59)) -> 25
B78: =COUNTIF($P$43:$P$47, true) -> 0 | C78: {=$J$43:$O$47}
B94: =COUNTIF($W$43:$W$47, true) -> 0 | C94: {=$Q$43:$V$47}
...

Sheet Mart
B3: Mart | I3: Odatlar soni | O3: Bajarilgan odatlar soni | V3: Oylik Progres | AB3: Progres %
I4: =SUM(countA($B$10:$B$21),$I$62) -> 0 | O4: =SUM(COUNTIF($C$10:$AG$21, true),$J$62) -> 0 | V4: =IFERROR(__xludf.DUMMYFUNCTION("iferror(SPARKLINE($AB$4:$AF$4,{""charttype"",""bar"";""max"",1;""color1"",""#c9e4b2""}))"),"") | AB4: =$O$4/SUM(COUNTA($C$10:$AG$21),$K$62) -> 0
B7: Kundalik vazifalar | C7: Hafta 1 | J7: Hafta 2 | Q7: Hafta 3 | X7: Hafta 4 | AI7: Analiz | AK7: Progres
C8: =weekday(date(Dashboard!$Q$3,$AG$45,C9),1) -> 7 | D8: =weekday(date(Dashboard!$Q$3,$AG$45,D9),1) -> 1 | E8: =weekday(date(Dashboard!$Q$3,$AG$45,E9),1) -> 2 | F8: =weekday(date(Dashboard!$Q$3,$AG$45,F9),1) -> 3 | G8: =weekday(date(Dashboard!$Q$3,$AG$45,G9),1) -> 4 | H8: =weekday(date(Dashboard!$Q$3,$AG$45,H9),1) -> 5 | I8: =weekday(date(Dashboard!$Q$3,$AG$45,I9),1) -> 6 | J8: =weekday(date(Dashboard!$Q$3,$AG$45,J9),1) -> 7 | ... AG8: =weekday(date(Dashboard!$Q$3,$AG$45,AG9),1) -> 2
B9: =TODAY() -> 46025 | C9: 1 | D9: 2 | E9: 3 | F9: 4 | G9: 5 | H9: 6 | I9: 7 | J9: 8 | K9: 9 | L9: 10 | M9: 11 | N9: 12 | O9: 13 | P9: 14 | Q9: 15 | R9: 16 | S9: 17 | T9: 18 | U9: 19 | V9: 20 | W9: 21 | X9: 22 | Y9: 23 | Z9: 24 | AA9: 25 | AB9: 26 | AC9: 27 | AD9: 28 | AE9: 29 | AF9: 30 | AG9: 31 | AI9: Maqsad | AJ9: Jami
C10: FALSE | D10: FALSE | E10: FALSE | F10: FALSE | G10: FALSE | H10: FALSE | I10: FALSE | J10: FALSE | K10: FALSE | L10: FALSE | M10: FALSE | N10: FALSE | O10: FALSE | P10: FALSE | Q10: FALSE | R10: FALSE | S10: FALSE | T10: FALSE | U10: FALSE | V10: FALSE | W10: FALSE | X10: FALSE | Y10: FALSE | Z10: FALSE | AA10: FALSE | AB10: FALSE | AC10: FALSE | AD10: FALSE | AE10: FALSE | AF10: FALSE | AG10: FALSE | AJ10: {=MMULT(N($C$10:$AG$21), TRANSPOSE(COLUMN($C$10:$AG$21)^0))} -> 0 | AK10: =IFERROR(__xludf.DUMMYFUNCTION("iferror(SPARKLINE(AJ10/AI10,{""charttype"",""bar"";""max"",1;""color1"",""#c9e4b2""}))"),"")
C11: FALSE | D11: FALSE | E11: FALSE | F11: FALSE | G11: FALSE | H11: FALSE | I11: FALSE | J11: FALSE | K11: FALSE | L11: FALSE | M11: FALSE | N11: FALSE | O11: FALSE | P11: FALSE | Q11: FALSE | R11: FALSE | S11: FALSE | T11: FALSE | U11: FALSE | V11: FALSE | W11: FALSE | X11: FALSE | Y11: FALSE | Z11: FALSE | AA11: FALSE | AB11: FALSE | AC11: FALSE | AD11: FALSE | AE11: FALSE | AF11: FALSE | AG11: FALSE | AJ11: 0 | AK11: =IFERROR(__xludf.DUMMYFUNCTION("iferror(SPARKLINE(AJ11/AI11,{""charttype"",""bar"";""max"",1;""color1"",""#c9e4b2""}))"),"")
C12: FALSE | D12: FALSE | E12: FALSE | F12: FALSE | G12: FALSE | H12: FALSE | I12: FALSE | J12: FALSE | K12: FALSE | L12: FALSE | M12: FALSE | N12: FALSE | O12: FALSE | P12: FALSE | Q12: FALSE | R12: FALSE | S12: FALSE | T12: FALSE | U12: FALSE | V12: FALSE | W12: FALSE | X12: FALSE | Y12: FALSE | Z12: FALSE | AA12: FALSE | AB12: FALSE | AC12: FALSE | AD12: FALSE | AE12: FALSE | AF12: FALSE | AG12: FALSE | AJ12: 0 | AK12: =IFERROR(__xludf.DUMMYFUNCTION("iferror(SPARKLINE(AJ12/AI12,{""charttype"",""bar"";""max"",1;""color1"",""#c9e4b2""}))"),"")
C13: FALSE | D13: FALSE | E13: FALSE | F13: FALSE | G13: FALSE | H13: FALSE | I13: FALSE | J13: FALSE | K13: FALSE | L13: FALSE | M13: FALSE | N13: FALSE | O13: FALSE | P13: FALSE | Q13: FALSE | R13: FALSE | S13: FALSE | T13: FALSE | U13: FALSE | V13: FALSE | W13: FALSE | X13: FALSE | Y13: FALSE | Z13: FALSE | AA13: FALSE | AB13: FALSE | AC13: FALSE | AD13: FALSE | AE13: FALSE | AF13: FALSE | AG13: FALSE | AJ13: 0 | AK13: =IFERROR(__xludf.DUMMYFUNCTION("iferror(SPARKLINE(AJ13/AI13,{""charttype"",""bar"";""max"",1;""color1"",""#c9e4b2""}))"),"")
C14: FALSE | D14: FALSE | E14: FALSE | F14: FALSE | G14: FALSE | H14: FALSE | I14: FALSE | J14: FALSE | K14: FALSE | L14: FALSE | M14: FALSE | N14: FALSE | O14: FALSE | P14: FALSE | Q14: FALSE | R14: FALSE | S14: FALSE | T14: FALSE | U14: FALSE | V14: FALSE | W14: FALSE | X14: FALSE | Y14: FALSE | Z14: FALSE | AA14: FALSE | AB14: FALSE | AC14: FALSE | AD14: FALSE | AE14: FALSE | AF14: FALSE | AG14: FALSE | AJ14: 0 | AK14: =IFERROR(__xludf.DUMMYFUNCTION("iferror(SPARKLINE(AJ14/AI14,{""charttype"",""bar"";""max"",1;""color1"",""#c9e4b2""}))"),"")
C15: FALSE | D15: FALSE | E15: FALSE | F15: FALSE | G15: FALSE | H15: FALSE | I15: FALSE | J15: FALSE | K15: FALSE | L15: FALSE | M15: FALSE | N15: FALSE | O15: FALSE | P15: FALSE | Q15: FALSE | R15: FALSE | S15: FALSE | T15: FALSE | U15: FALSE | V15: FALSE | W15: FALSE | X15: FALSE | Y15: FALSE | Z15: FALSE | AA15: FALSE | AB15: FALSE | AC15: FALSE | AD15: FALSE | AE15: FALSE | AF15: FALSE | AG15: FALSE | AJ15: 0 | AK15: =IFERROR(__xludf.DUMMYFUNCTION("iferror(SPARKLINE(AJ15/AI15,{""charttype"",""bar"";""max"",1;""color1"",""#c9e4b2""}))"),"")
C16: FALSE | D16: FALSE | E16: FALSE | F16: FALSE | G16: FALSE | H16: FALSE | I16: FALSE | J16: FALSE | K16: FALSE | L16: FALSE | M16: FALSE | N16: FALSE | O16: FALSE | P16: FALSE | Q16: FALSE | R16: FALSE | S16: FALSE | T16: FALSE | U16: FALSE | V16: FALSE | W16: FALSE | X16: FALSE | Y16: FALSE | Z16: FALSE | AA16: FALSE | AB16: FALSE | AC16: FALSE | AD16: FALSE | AE16: FALSE | AF16: FALSE | AG16: FALSE | AJ16: 0 | AK16: =IFERROR(__xludf.DUMMYFUNCTION("iferror(SPARKLINE(AJ16/AI16,{""charttype"",""bar"";""max"",1;""color1"",""#c9e4b2""}))"),"")
C17: FALSE | D17: FALSE | E17: FALSE | F17: FALSE | G17: FALSE | H17: FALSE | I17: FALSE | J17: FALSE | K17: FALSE | L17: FALSE | M17: FALSE | N17: FALSE | O17: FALSE | P17: FALSE | Q17: FALSE | R17: FALSE | S17: FALSE | T17: FALSE | U17: FALSE | V17: FALSE | W17: FALSE | X17: FALSE | Y17: FALSE | Z17: FALSE | AA17: FALSE | AB17: FALSE | AC17: FALSE | AD17: FALSE | AE17: FALSE | AF17: FALSE | AG17: FALSE | AJ17: 0 | AK17: =IFERROR(__xludf.DUMMYFUNCTION("iferror(SPARKLINE(AJ17/AI17,{""charttype"",""bar"";""max"",1;""color1"",""#c9e4b2""}))"),"")
C18: FALSE | D18: FALSE | E18: FALSE | F18: FALSE | G18: FALSE | H18: FALSE | I18: FALSE | J18: FALSE | K18: FALSE | L18: FALSE | M18: FALSE | N18: FALSE | O18: FALSE | P18: FALSE | Q18: FALSE | R18: FALSE | S18: FALSE | T18: FALSE | U18: FALSE | V18: FALSE | W18: FALSE | X18: FALSE | Y18: FALSE | Z18: FALSE | AA18: FALSE | AB18: FALSE | AC18: FALSE | AD18: FALSE | AE18: FALSE | AF18: FALSE | AG18: FALSE | AJ18: 0 | AK18: =IFERROR(__xludf.DUMMYFUNCTION("iferror(SPARKLINE(AJ18/AI18,{""charttype"",""bar"";""max"",1;""color1"",""#c9e4b2""}))"),"")
C19: FALSE | D19: FALSE | E19: FALSE | F19: FALSE | G19: FALSE | H19: FALSE | I19: FALSE | J19: FALSE | K19: FALSE | L19: FALSE | M19: FALSE | N19: FALSE | O19: FALSE | P19: FALSE | Q19: FALSE | R19: FALSE | S19: FALSE | T19: FALSE | U19: FALSE | V19: FALSE | W19: FALSE | X19: FALSE | Y19: FALSE | Z19: FALSE | AA19: FALSE | AB19: FALSE | AC19: FALSE | AD19: FALSE | AE19: FALSE | AF19: FALSE | AG19: FALSE | AJ19: 0 | AK19: =IFERROR(__xludf.DUMMYFUNCTION("iferror(SPARKLINE(AJ19/AI19,{""charttype"",""bar"";""max"",1;""color1"",""#c9e4b2""}))"),"")
C20: FALSE | D20: FALSE | E20: FALSE | F20: FALSE | G20: FALSE | H20: FALSE | I20: FALSE | J20: FALSE | K20: FALSE | L20: FALSE | M20: FALSE | N20: FALSE | O20: FALSE | P20: FALSE | Q20: FALSE | R20: FALSE | S20: FALSE | T20: FALSE | U20: FALSE | V20: FALSE | W20: FALSE | X20: FALSE | Y20: FALSE | Z20: FALSE | AA20: FALSE | AB20: FALSE | AC20: FALSE | AD20: FALSE | AE20: FALSE | AF20: FALSE | AG20: FALSE | AJ20: 0 | AK20: =IFERROR(__xludf.DUMMYFUNCTION("iferror(SPARKLINE(AJ20/AI20,{""charttype"",""bar"";""max"",1;""color1"",""#c9e4b2""}))"),"")
C21: FALSE | D21: FALSE | E21: FALSE | F21: FALSE | G21: FALSE | H21: FALSE | I21: FALSE | J21: FALSE | K21: FALSE | L21: FALSE | M21: FALSE | N21: FALSE | O21: FALSE | P21: FALSE | Q21: FALSE | R21: FALSE | S21: FALSE | T21: FALSE | U21: FALSE | V21: FALSE | W21: FALSE | X21: FALSE | Y21: FALSE | Z21: FALSE | AA21: FALSE | AB21: FALSE | AC21: FALSE | AD21: FALSE | AE21: FALSE | AF21: FALSE | AG21: FALSE | AJ21: 0 | AK21: =IFERROR(__xludf.DUMMYFUNCTION("iferror(SPARKLINE(AJ21/AI21,{""charttype"",""bar"";""max"",1;""color1"",""#c9e4b2""}))"),"")
B23: Progres % | C23: =COUNTIF(C10:C21, TRUE)/COUNTA(C10:C21) -> 0 | D23: =COUNTIF(D10:D21, TRUE)/COUNTA(D10:D21) -> 0 | E23: =COUNTIF(E10:E21, TRUE)/COUNTA(E10:E21) -> 0 | F23: =COUNTIF(F10:F21, TRUE)/COUNTA(F10:F21) -> 0 | G23: =COUNTIF(G10:G21, TRUE)/COUNTA(G10:G21) -> 0 | H23: =COUNTIF(H10:H21, TRUE)/COUNTA(H10:H21) -> 0 | I23: =COUNTIF(I10:I21, TRUE)/COUNTA(I10:I21) -> 0 | J23: =COUNTIF(J10:J21, TRUE)/COUNTA(J10:J21) -> 0 | ... AG23: =COUNTIF(AG10:AG21, TRUE)/COUNTA(AG10:AG21) -> 0
B24: To'ldirilgan | C24: =COUNTIF(C10:C21, true) -> 0 | D24: =COUNTIF(D10:D21, true) -> 0 | E24: =COUNTIF(E10:E21, true) -> 0 | F24: =COUNTIF(F10:F21, true) -> 0 | G24: =COUNTIF(G10:G21, true) -> 0 | H24: =COUNTIF(H10:H21, true) -> 0 | I24: =COUNTIF(I10:I21, true) -> 0 | J24: =COUNTIF(J10:J21, true) -> 0 | ... AG24: =COUNTIF(AG10:AG21, true) -> 0
B25: To'ldirilmagan | C25: =COUNTIF(C10:C21, false) -> 12 | D25: =COUNTIF(D10:D21, false) -> 12 | E25: =COUNTIF(E10:E21, false) -> 12 | F25: =COUNTIF(F10:F21, false) -> 12 | G25: =COUNTIF(G10:G21, false) -> 12 | H25: =COUNTIF(H10:H21, false) -> 12 | I25: =COUNTIF(I10:I21, false) -> 12 | J25: =COUNTIF(J10:J21, false) -> 12 | ... AG25: =COUNTIF(AG10:AG21, false) -> 12
B36: Ежедневные размышления | AI36: O'rtacha qiymat
B37: Kayfiyat | AI37: =iferror(Average(C37:AG37), "")
B38: Energiya | AI38: =iferror(Average(C38:AG38), "")
B39: Motivatsiya | AI39: =iferror(Average(C39:AG39), "")
B42: Haftalik | C42: Hafta 1 | J42: Hafta 2 | Q42: Hafta 3 | X42: Hafta 4
I43: FALSE | P43: FALSE | W43: FALSE | AD43: FALSE
I44: FALSE | P44: FALSE | W44: FALSE | AD44: FALSE | AG44: January
I45: FALSE | P45: FALSE | W45: FALSE | AD45: FALSE | AG45: 3
I46: FALSE | P46: FALSE | W46: FALSE | AD46: FALSE
I47: FALSE | P47: FALSE | W47: FALSE | AD47: FALSE
B49: Haftalik fikrlar
B54: Oylik | C54: Ushbu oy maqsadlari
P55: FALSE
P56: FALSE
P57: FALSE
P58: FALSE
P59: FALSE
B62: =COUNTIF($I$43:$I$47, true) -> 0 | C62: {=$C$43:$H$47} | I62: {=COUNTA(UNIQUE($C$62:$C$140))} -> 0 | J62: =sum($B$62,$B$78,$B$110,$B$126) -> 0 | K62: =sum(COUNTA($I$43:$I$47),COUNTA($P$43:$P$47),COUNTA($W$43:$W$47),COUNTA($AD$43:$AD$47),COUNTA($P$55:$P$59)) -> 25
B78: =COUNTIF($P$43:$P$47, true) -> 0 | C78: {=$J$43:$O$47}
B94: =COUNTIF($W$43:$W$47, true) -> 0 | C94: {=$Q$43:$V$47}
...

Sheet Apr
B3: Aprel | I3: Odatlar soni | O3: Bajarilgan odatlar soni | V3: Oylik Progres | AB3: Progres %
I4: =SUM(countA($B$10:$B$21),$I$62) -> 0 | O4: =SUM(COUNTIF($C$10:$AG$21, true),$J$62) -> 0 | V4: =IFERROR(__xludf.DUMMYFUNCTION("iferror(SPARKLINE($AB$4:$AF$4,{""charttype"",""bar"";""max"",1;""color1"",""#c9e4b2""}))"),"") | AB4: =$O$4/SUM(COUNTA($C$10:$AG$21),$K$62) -> 0
B7: Kundalik vazifalar | C7: Hafta 1 | J7: Hafta 2 | Q7: Hafta 3 | X7: Hafta 4 | AI7: Analiz | AK7: Progres
C8: =weekday(date(Dashboard!$Q$3,$AG$45,C9),1) -> 3 | D8: =weekday(date(Dashboard!$Q$3,$AG$45,D9),1) -> 4 | E8: =weekday(date(Dashboard!$Q$3,$AG$45,E9),1) -> 5 | F8: =weekday(date(Dashboard!$Q$3,$AG$45,F9),1) -> 6 | G8: =weekday(date(Dashboard!$Q$3,$AG$45,G9),1) -> 7 | H8: =weekday(date(Dashboard!$Q$3,$AG$45,H9),1) -> 1 | I8: =weekday(date(Dashboard!$Q$3,$AG$45,I9),1) -> 2 | J8: =weekday(date(Dashboard!$Q$3,$AG$45,J9),1) -> 3 | ... AG8: =weekday(date(Dashboard!$Q$3,$AG$45,AG9),1) -> 5
B9: =TODAY() -> 46025 | C9: 1 | D9: 2 | E9: 3 | F9: 4 | G9: 5 | H9: 6 | I9: 7 | J9: 8 | K9: 9 | L9: 10 | M9: 11 | N9: 12 | O9: 13 | P9: 14 | Q9: 15 | R9: 16 | S9: 17 | T9: 18 | U9: 19 | V9: 20 | W9: 21 | X9: 22 | Y9: 23 | Z9: 24 | AA9: 25 | AB9: 26 | AC9: 27 | AD9: 28 | AE9: 29 | AF9: 30 | AG9: 31 | AI9: Maqsad | AJ9: Jami
C10: FALSE | D10: FALSE | E10: FALSE | F10: FALSE | G10: FALSE | H10: FALSE | I10: FALSE | J10: FALSE | K10: FALSE | L10: FALSE | M10: FALSE | N10: FALSE | O10: FALSE | P10: FALSE | Q10: FALSE | R10: FALSE | S10: FALSE | T10: FALSE | U10: FALSE | V10: FALSE | W10: FALSE | X10: FALSE | Y10: FALSE | Z10: FALSE | AA10: FALSE | AB10: FALSE | AC10: FALSE | AD10: FALSE | AE10: FALSE | AF10: FALSE | AG10: FALSE | AJ10: {=MMULT(N($C$10:$AG$21), TRANSPOSE(COLUMN($C$10:$AG$21)^0))} -> 0 | AK10: =IFERROR(__xludf.DUMMYFUNCTION("iferror(SPARKLINE(AJ10/AI10,{""charttype"",""bar"";""max"",1;""color1"",""#c9e4b2""}))"),"")
C11: FALSE | D11: FALSE | E11: FALSE | F11: FALSE | G11: FALSE | H11: FALSE | I11: FALSE | J11: FALSE | K11: FALSE | L11: FALSE | M11: FALSE | N11: FALSE | O11: FALSE | P11: FALSE | Q11: FALSE | R11: FALSE | S11: FALSE | T11: FALSE | U11: FALSE | V11: FALSE | W11: FALSE | X11: FALSE | Y11: FALSE | Z11: FALSE | AA11: FALSE | AB11: FALSE | AC11: FALSE | AD11: FALSE | AE11: FALSE | AF11: FALSE | AG11: FALSE | AJ11: 0 | AK11: =IFERROR(__xludf.DUMMYFUNCTION("iferror(SPARKLINE(AJ11/AI11,{""charttype"",""bar"";""max"",1;""color1"",""#c9e4b2""}))"),"")
C12: FALSE | D12: FALSE | E12: FALSE | F12: FALSE | G12: FALSE | H12: FALSE | I12: FALSE | J12: FALSE | K12: FALSE | L12: FALSE | M12: FALSE | N12: FALSE | O12: FALSE | P12: FALSE | Q12: FALSE | R12: FALSE | S12: FALSE | T12: FALSE | U12: FALSE | V12: FALSE | W12: FALSE | X12: FALSE | Y12: FALSE | Z12: FALSE | AA12: FALSE | AB12: FALSE | AC12: FALSE | AD12: FALSE | AE12: FALSE | AF12: FALSE | AG12: FALSE | AJ12: 0 | AK12: =IFERROR(__xludf.DUMMYFUNCTION("iferror(SPARKLINE(AJ12/AI12,{""charttype"",""bar"";""max"",1;""color1"",""#c9e4b2""}))"),"")
C13: FALSE | D13: FALSE | E13: FALSE | F13: FALSE | G13: FALSE | H13: FALSE | I13: FALSE | J13: FALSE | K13: FALSE | L13: FALSE | M13: FALSE | N13: FALSE | O13: FALSE | P13: FALSE | Q13: FALSE | R13: FALSE | S13: FALSE | T13: FALSE | U13: FALSE | V13: FALSE | W13: FALSE | X13: FALSE | Y13: FALSE | Z13: FALSE | AA13: FALSE | AB13: FALSE | AC13: FALSE | AD13: FALSE | AE13: FALSE | AF13: FALSE | AG13: FALSE | AJ13: 0 | AK13: =IFERROR(__xludf.DUMMYFUNCTION("iferror(SPARKLINE(AJ13/AI13,{""charttype"",""bar"";""max"",1;""color1"",""#c9e4b2""}))"),"")
C14: FALSE | D14: FALSE | E14: FALSE | F14: FALSE | G14: FALSE | H14: FALSE | I14: FALSE | J14: FALSE | K14: FALSE | L14: FALSE | M14: FALSE | N14: FALSE | O14: FALSE | P14: FALSE | Q14: FALSE | R14: FALSE | S14: FALSE | T14: FALSE | U14: FALSE | V14: FALSE | W14: FALSE | X14: FALSE | Y14: FALSE | Z14: FALSE | AA14: FALSE | AB14: FALSE | AC14: FALSE | AD14: FALSE | AE14: FALSE | AF14: FALSE | AG14: FALSE | AJ14: 0 | AK14: =IFERROR(__xludf.DUMMYFUNCTION("iferror(SPARKLINE(AJ14/AI14,{""charttype"",""bar"";""max"",1;""color1"",""#c9e4b2""}))"),"")
C15: FALSE | D15: FALSE | E15: FALSE | F15: FALSE | G15: FALSE | H15: FALSE | I15: FALSE | J15: FALSE | K15: FALSE | L15: FALSE | M15: FALSE | N15: FALSE | O15: FALSE | P15: FALSE | Q15: FALSE | R15: FALSE | S15: FALSE | T15: FALSE | U15: FALSE | V15: FALSE | W15: FALSE | X15: FALSE | Y15: FALSE | Z15: FALSE | AA15: FALSE | AB15: FALSE | AC15: FALSE | AD15: FALSE | AE15: FALSE | AF15: FALSE | AG15: FALSE | AJ15: 0 | AK15: =IFERROR(__xludf.DUMMYFUNCTION("iferror(SPARKLINE(AJ15/AI15,{""charttype"",""bar"";""max"",1;""color1"",""#c9e4b2""}))"),"")
C16: FALSE | D16: FALSE | E16: FALSE | F16: FALSE | G16: FALSE | H16: FALSE | I16: FALSE | J16: FALSE | K16: FALSE | L16: FALSE | M16: FALSE | N16: FALSE | O16: FALSE | P16: FALSE | Q16: FALSE | R16: FALSE | S16: FALSE | T16: FALSE | U16: FALSE | V16: FALSE | W16: FALSE | X16: FALSE | Y16: FALSE | Z16: FALSE | AA16: FALSE | AB16: FALSE | AC16: FALSE | AD16: FALSE | AE16: FALSE | AF16: FALSE | AG16: FALSE | AJ16: 0 | AK16: =IFERROR(__xludf.DUMMYFUNCTION("iferror(SPARKLINE(AJ16/AI16,{""charttype"",""bar"";""max"",1;""color1"",""#c9e4b2""}))"),"")
C17: FALSE | D17: FALSE | E17: FALSE | F17: FALSE | G17: FALSE | H17: FALSE | I17: FALSE | J17: FALSE | K17: FALSE | L17: FALSE | M17: FALSE | N17: FALSE | O17: FALSE | P17: FALSE | Q17: FALSE | R17: FALSE | S17: FALSE | T17: FALSE | U17: FALSE | V17: FALSE | W17: FALSE | X17: FALSE | Y17: FALSE | Z17: FALSE | AA17: FALSE | AB17: FALSE | AC17: FALSE | AD17: FALSE | AE17: FALSE | AF17: FALSE | AG17: FALSE | AJ17: 0 | AK17: =IFERROR(__xludf.DUMMYFUNCTION("iferror(SPARKLINE(AJ17/AI17,{""charttype"",""bar"";""max"",1;""color1"",""#c9e4b2""}))"),"")
C18: FALSE | D18: FALSE | E18: FALSE | F18: FALSE | G18: FALSE | H18: FALSE | I18: FALSE | J18: FALSE | K18: FALSE | L18: FALSE | M18: FALSE | N18: FALSE | O18: FALSE | P18: FALSE | Q18: FALSE | R18: FALSE | S18: FALSE | T18: FALSE | U18: FALSE | V18: FALSE | W18: FALSE | X18: FALSE | Y18: FALSE | Z18: FALSE | AA18: FALSE | AB18: FALSE | AC18: FALSE | AD18: FALSE | AE18: FALSE | AF18: FALSE | AG18: FALSE | AJ18: 0 | AK18: =IFERROR(__xludf.DUMMYFUNCTION("iferror(SPARKLINE(AJ18/AI18,{""charttype"",""bar"";""max"",1;""color1"",""#c9e4b2""}))"),"")
C19: FALSE | D19: FALSE | E19: FALSE | F19: FALSE | G19: FALSE | H19: FALSE | I19: FALSE | J19: FALSE | K19: FALSE | L19: FALSE | M19: FALSE | N19: FALSE | O19: FALSE | P19: FALSE | Q19: FALSE | R19: FALSE | S19: FALSE | T19: FALSE | U19: FALSE | V19: FALSE | W19: FALSE | X19: FALSE | Y19: FALSE | Z19: FALSE | AA19: FALSE | AB19: FALSE | AC19: FALSE | AD19: FALSE | AE19: FALSE | AF19: FALSE | AG19: FALSE | AJ19: 0 | AK19: =IFERROR(__xludf.DUMMYFUNCTION("iferror(SPARKLINE(AJ19/AI19,{""charttype"",""bar"";""max"",1;""color1"",""#c9e4b2""}))"),"")
C20: FALSE | D20: FALSE | E20: FALSE | F20: FALSE | G20: FALSE | H20: FALSE | I20: FALSE | J20: FALSE | K20: FALSE | L20: FALSE | M20: FALSE | N20: FALSE | O20: FALSE | P20: FALSE | Q20: FALSE | R20: FALSE | S20: FALSE | T20: FALSE | U20: FALSE | V20: FALSE | W20: FALSE | X20: FALSE | Y20: FALSE | Z20: FALSE | AA20: FALSE | AB20: FALSE | AC20: FALSE | AD20: FALSE | AE20: FALSE | AF20: FALSE | AG20: FALSE | AJ20: 0 | AK20: =IFERROR(__xludf.DUMMYFUNCTION("iferror(SPARKLINE(AJ20/AI20,{""charttype"",""bar"";""max"",1;""color1"",""#c9e4b2""}))"),"")
C21: FALSE | D21: FALSE | E21: FALSE | F21: FALSE | G21: FALSE | H21: FALSE | I21: FALSE | J21: FALSE | K21: FALSE | L21: FALSE | M21: FALSE | N21: FALSE | O21: FALSE | P21: FALSE | Q21: FALSE | R21: FALSE | S21: FALSE | T21: FALSE | U21: FALSE | V21: FALSE | W21: FALSE | X21: FALSE | Y21: FALSE | Z21: FALSE | AA21: FALSE | AB21: FALSE | AC21: FALSE | AD21: FALSE | AE21: FALSE | AF21: FALSE | AG21: FALSE | AJ21: 0 | AK21: =IFERROR(__xludf.DUMMYFUNCTION("iferror(SPARKLINE(AJ21/AI21,{""charttype"",""bar"";""max"",1;""color1"",""#c9e4b2""}))"),"")
B23: Progres % | C23: =COUNTIF(C10:C21, TRUE)/COUNTA(C10:C21) -> 0 | D23: =COUNTIF(D10:D21, TRUE)/COUNTA(D10:D21) -> 0 | E23: =COUNTIF(E10:E21, TRUE)/COUNTA(E10:E21) -> 0 | F23: =COUNTIF(F10:F21, TRUE)/COUNTA(F10:F21) -> 0 | G23: =COUNTIF(G10:G21, TRUE)/COUNTA(G10:G21) -> 0 | H23: =COUNTIF(H10:H21, TRUE)/COUNTA(H10:H21) -> 0 | I23: =COUNTIF(I10:I21, TRUE)/COUNTA(I10:I21) -> 0 | J23: =COUNTIF(J10:J21, TRUE)/COUNTA(J10:J21) -> 0 | ... AG23: =COUNTIF(AG10:AG21, TRUE)/COUNTA(AG10:AG21) -> 0
B24: To'ldirilgan | C24: =COUNTIF(C10:C21, true) -> 0 | D24: =COUNTIF(D10:D21, true) -> 0 | E24: =COUNTIF(E10:E21, true) -> 0 | F24: =COUNTIF(F10:F21, true) -> 0 | G24: =COUNTIF(G10:G21, true) -> 0 | H24: =COUNTIF(H10:H21, true) -> 0 | I24: =COUNTIF(I10:I21, true) -> 0 | J24: =COUNTIF(J10:J21, true) -> 0 | ... AG24: =COUNTIF(AG10:AG21, true) -> 0
B25: To'ldirilmagan | C25: =COUNTIF(C10:C21, false) -> 12 | D25: =COUNTIF(D10:D21, false) -> 12 | E25: =COUNTIF(E10:E21, false) -> 12 | F25: =COUNTIF(F10:F21, false) -> 12 | G25: =COUNTIF(G10:G21, false) -> 12 | H25: =COUNTIF(H10:H21, false) -> 12 | I25: =COUNTIF(I10:I21, false) -> 12 | J25: =COUNTIF(J10:J21, false) -> 12 | ... AG25: =COUNTIF(AG10:AG21, false) -> 12
B36: Kundalik holat | AI36: O'rtacha qiymat
B37: Kayfiyat | AI37: =iferror(Average(C37:AG37), "")
B38: Energiya | AI38: =iferror(Average(C38:AG38), "")
B39: Motivatsiya | AI39: =iferror(Average(C39:AG39), "")
B42: Haftalik | C42: Hafta 1 | J42: Hafta 2 | Q42: Hafta 3 | X42: Hafta 4
I43: FALSE | P43: FALSE | W43: FALSE | AD43: FALSE
I44: FALSE | P44: FALSE | W44: FALSE | AD44: FALSE | AG44: January
I45: FALSE | P45: FALSE | W45: FALSE | AD45: FALSE | AG45: 4
I46: FALSE | P46: FALSE | W46: FALSE | AD46: FALSE
I47: FALSE | P47: FALSE | W47: FALSE | AD47: FALSE
B49: Haftalik fikrlar
B54: Oylik | C54: Ushbu oy maqsadlari
P55: FALSE
P56: FALSE
P57: FALSE
P58: FALSE
P59: FALSE
B62: =COUNTIF($I$43:$I$47, true) -> 0 | C62: {=$C$43:$H$47} | I62: {=COUNTA(UNIQUE($C$62:$C$140))} -> 0 | J62: =sum($B$62,$B$78,$B$110,$B$126) -> 0 | K62: =sum(COUNTA($I$43:$I$47),COUNTA($P$43:$P$47),COUNTA($W$43:$W$47),COUNTA($AD$43:$AD$47),COUNTA($P$55:$P$59)) -> 25
B78: =COUNTIF($P$43:$P$47, true) -> 0 | C78: {=$J$43:$O$47}
B94: =COUNTIF($W$43:$W$47, true) -> 0 | C94: {=$Q$43:$V$47}
...

Sheet May
B3: Май | I3: Odatlar soni | O3: Bajarilgan odatlar soni | V3: Oylik Progres | AB3: Progres %
I4: =SUM(countA($B$10:$B$21),$I$62) -> 0 | O4: =SUM(COUNTIF($C$10:$AG$21, true),$J$62) -> 0 | V4: =IFERROR(__xludf.DUMMYFUNCTION("iferror(SPARKLINE($AB$4:$AF$4,{""charttype"",""bar"";""max"",1;""color1"",""#c9e4b2""}))"),"") | AB4: =$O$4/SUM(COUNTA($C$10:$AG$21),$K$62) -> 0
B7: Kundalik vazifalar | C7: Hafta 1 | J7: Hafta 2 | Q7: Hafta 3 | X7: Hafta 4 | AI7: Analiz | AK7: Progres
C8: =weekday(date(Dashboard!$Q$3,$AG$45,C9),1) -> 5 | D8: =weekday(date(Dashboard!$Q$3,$AG$45,D9),1) -> 6 | E8: =weekday(date(Dashboard!$Q$3,$AG$45,E9),1) -> 7 | F8: =weekday(date(Dashboard!$Q$3,$AG$45,F9),1) -> 1 | G8: =weekday(date(Dashboard!$Q$3,$AG$45,G9),1) -> 2 | H8: =weekday(date(Dashboard!$Q$3,$AG$45,H9),1) -> 3 | I8: =weekday(date(Dashboard!$Q$3,$AG$45,I9),1) -> 4 | J8: =weekday(date(Dashboard!$Q$3,$AG$45,J9),1) -> 5 | ... AG8: =weekday(date(Dashboard!$Q$3,$AG$45,AG9),1) -> 7
B9: =TODAY() -> 46025 | C9: 1 | D9: 2 | E9: 3 | F9: 4 | G9: 5 | H9: 6 | I9: 7 | J9: 8 | K9: 9 | L9: 10 | M9: 11 | N9: 12 | O9: 13 | P9: 14 | Q9: 15 | R9: 16 | S9: 17 | T9: 18 | U9: 19 | V9: 20 | W9: 21 | X9: 22 | Y9: 23 | Z9: 24 | AA9: 25 | AB9: 26 | AC9: 27 | AD9: 28 | AE9: 29 | AF9: 30 | AG9: 31 | AI9: Maqsad | AJ9: Jami
C10: FALSE | D10: FALSE | E10: FALSE | F10: FALSE | G10: FALSE | H10: FALSE | I10: FALSE | J10: FALSE | K10: FALSE | L10: FALSE | M10: FALSE | N10: FALSE | O10: FALSE | P10: FALSE | Q10: FALSE | R10: FALSE | S10: FALSE | T10: FALSE | U10: FALSE | V10: FALSE | W10: FALSE | X10: FALSE | Y10: FALSE | Z10: FALSE | AA10: FALSE | AB10: FALSE | AC10: FALSE | AD10: FALSE | AE10: FALSE | AF10: FALSE | AG10: FALSE | AJ10: {=MMULT(N($C$10:$AG$21), TRANSPOSE(COLUMN($C$10:$AG$21)^0))} -> 0 | AK10: =IFERROR(__xludf.DUMMYFUNCTION("iferror(SPARKLINE(AJ10/AI10,{""charttype"",""bar"";""max"",1;""color1"",""#c9e4b2""}))"),"")
C11: FALSE | D11: FALSE | E11: FALSE | F11: FALSE | G11: FALSE | H11: FALSE | I11: FALSE | J11: FALSE | K11: FALSE | L11: FALSE | M11: FALSE | N11: FALSE | O11: FALSE | P11: FALSE | Q11: FALSE | R11: FALSE | S11: FALSE | T11: FALSE | U11: FALSE | V11: FALSE | W11: FALSE | X11: FALSE | Y11: FALSE | Z11: FALSE | AA11: FALSE | AB11: FALSE | AC11: FALSE | AD11: FALSE | AE11: FALSE | AF11: FALSE | AG11: FALSE | AJ11: 0 | AK11: =IFERROR(__xludf.DUMMYFUNCTION("iferror(SPARKLINE(AJ11/AI11,{""charttype"",""bar"";""max"",1;""color1"",""#c9e4b2""}))"),"")
C12: FALSE | D12: FALSE | E12: FALSE | F12: FALSE | G12: FALSE | H12: FALSE | I12: FALSE | J12: FALSE | K12: FALSE | L12: FALSE | M12: FALSE | N12: FALSE | O12: FALSE | P12: FALSE | Q12: FALSE | R12: FALSE | S12: FALSE | T12: FALSE | U12: FALSE | V12: FALSE | W12: FALSE | X12: FALSE | Y12: FALSE | Z12: FALSE | AA12: FALSE | AB12: FALSE | AC12: FALSE | AD12: FALSE | AE12: FALSE | AF12: FALSE | AG12: FALSE | AJ12: 0 | AK12: =IFERROR(__xludf.DUMMYFUNCTION("iferror(SPARKLINE(AJ12/AI12,{""charttype"",""bar"";""max"",1;""color1"",""#c9e4b2""}))"),"")
C13: FALSE | D13: FALSE | E13: FALSE | F13: FALSE | G13: FALSE | H13: FALSE | I13: FALSE | J13: FALSE | K13: FALSE | L13: FALSE | M13: FALSE | N13: FALSE | O13: FALSE | P13: FALSE | Q13: FALSE | R13: FALSE | S13: FALSE | T13: FALSE | U13: FALSE | V13: FALSE | W13: FALSE | X13: FALSE | Y13: FALSE | Z13: FALSE | AA13: FALSE | AB13: FALSE | AC13: FALSE | AD13: FALSE | AE13: FALSE | AF13: FALSE | AG13: FALSE | AJ13: 0 | AK13: =IFERROR(__xludf.DUMMYFUNCTION("iferror(SPARKLINE(AJ13/AI13,{""charttype"",""bar"";""max"",1;""color1"",""#c9e4b2""}))"),"")
C14: FALSE | D14: FALSE | E14: FALSE | F14: FALSE | G14: FALSE | H14: FALSE | I14: FALSE | J14: FALSE | K14: FALSE | L14: FALSE | M14: FALSE | N14: FALSE | O14: FALSE | P14: FALSE | Q14: FALSE | R14: FALSE | S14: FALSE | T14: FALSE | U14: FALSE | V14: FALSE | W14: FALSE | X14: FALSE | Y14: FALSE | Z14: FALSE | AA14: FALSE | AB14: FALSE | AC14: FALSE | AD14: FALSE | AE14: FALSE | AF14: FALSE | AG14: FALSE | AJ14: 0 | AK14: =IFERROR(__xludf.DUMMYFUNCTION("iferror(SPARKLINE(AJ14/AI14,{""charttype"",""bar"";""max"",1;""color1"",""#c9e4b2""}))"),"")
C15: FALSE | D15: FALSE | E15: FALSE | F15: FALSE | G15: FALSE | H15: FALSE | I15: FALSE | J15: FALSE | K15: FALSE | L15: FALSE | M15: FALSE | N15: FALSE | O15: FALSE | P15: FALSE | Q15: FALSE | R15: FALSE | S15: FALSE | T15: FALSE | U15: FALSE | V15: FALSE | W15: FALSE | X15: FALSE | Y15: FALSE | Z15: FALSE | AA15: FALSE | AB15: FALSE | AC15: FALSE | AD15: FALSE | AE15: FALSE | AF15: FALSE | AG15: FALSE | AJ15: 0 | AK15: =IFERROR(__xludf.DUMMYFUNCTION("iferror(SPARKLINE(AJ15/AI15,{""charttype"",""bar"";""max"",1;""color1"",""#c9e4b2""}))"),"")
C16: FALSE | D16: FALSE | E16: FALSE | F16: FALSE | G16: FALSE | H16: FALSE | I16: FALSE | J16: FALSE | K16: FALSE | L16: FALSE | M16: FALSE | N16: FALSE | O16: FALSE | P16: FALSE | Q16: FALSE | R16: FALSE | S16: FALSE | T16: FALSE | U16: FALSE | V16: FALSE | W16: FALSE | X16: FALSE | Y16: FALSE | Z16: FALSE | AA16: FALSE | AB16: FALSE | AC16: FALSE | AD16: FALSE | AE16: FALSE | AF16: FALSE | AG16: FALSE | AJ16: 0 | AK16: =IFERROR(__xludf.DUMMYFUNCTION("iferror(SPARKLINE(AJ16/AI16,{""charttype"",""bar"";""max"",1;""color1"",""#c9e4b2""}))"),"")
C17: FALSE | D17: FALSE | E17: FALSE | F17: FALSE | G17: FALSE | H17: FALSE | I17: FALSE | J17: FALSE | K17: FALSE | L17: FALSE | M17: FALSE | N17: FALSE | O17: FALSE | P17: FALSE | Q17: FALSE | R17: FALSE | S17: FALSE | T17: FALSE | U17: FALSE | V17: FALSE | W17: FALSE | X17: FALSE | Y17: FALSE | Z17: FALSE | AA17: FALSE | AB17: FALSE | AC17: FALSE | AD17: FALSE | AE17: FALSE | AF17: FALSE | AG17: FALSE | AJ17: 0 | AK17: =IFERROR(__xludf.DUMMYFUNCTION("iferror(SPARKLINE(AJ17/AI17,{""charttype"",""bar"";""max"",1;""color1"",""#c9e4b2""}))"),"")
C18: FALSE | D18: FALSE | E18: FALSE | F18: FALSE | G18: FALSE | H18: FALSE | I18: FALSE | J18: FALSE | K18: FALSE | L18: FALSE | M18: FALSE | N18: FALSE | O18: FALSE | P18: FALSE | Q18: FALSE | R18: FALSE | S18: FALSE | T18: FALSE | U18: FALSE | V18: FALSE | W18: FALSE | X18: FALSE | Y18: FALSE | Z18: FALSE | AA18: FALSE | AB18: FALSE | AC18: FALSE | AD18: FALSE | AE18: FALSE | AF18: FALSE | AG18: FALSE | AJ18: 0 | AK18: =IFERROR(__xludf.DUMMYFUNCTION("iferror(SPARKLINE(AJ18/AI18,{""charttype"",""bar"";""max"",1;""color1"",""#c9e4b2""}))"),"")
C19: FALSE | D19: FALSE | E19: FALSE | F19: FALSE | G19: FALSE | H19: FALSE | I19: FALSE | J19: FALSE | K19: FALSE | L19: FALSE | M19: FALSE | N19: FALSE | O19: FALSE | P19: FALSE | Q19: FALSE | R19: FALSE | S19: FALSE | T19: FALSE | U19: FALSE | V19: FALSE | W19: FALSE | X19: FALSE | Y19: FALSE | Z19: FALSE | AA19: FALSE | AB19: FALSE | AC19: FALSE | AD19: FALSE | AE19: FALSE | AF19: FALSE | AG19: FALSE | AJ19: 0 | AK19: =IFERROR(__xludf.DUMMYFUNCTION("iferror(SPARKLINE(AJ19/AI19,{""charttype"",""bar"";""max"",1;""color1"",""#c9e4b2""}))"),"")
C20: FALSE | D20: FALSE | E20: FALSE | F20: FALSE | G20: FALSE | H20: FALSE | I20: FALSE | J20: FALSE | K20: FALSE | L20: FALSE | M20: FALSE | N20: FALSE | O20: FALSE | P20: FALSE | Q20: FALSE | R20: FALSE | S20: FALSE | T20: FALSE | U20: FALSE | V20: FALSE | W20: FALSE | X20: FALSE | Y20: FALSE | Z20: FALSE | AA20: FALSE | AB20: FALSE | AC20: FALSE | AD20: FALSE | AE20: FALSE | AF20: FALSE | AG20: FALSE | AJ20: 0 | AK20: =IFERROR(__xludf.DUMMYFUNCTION("iferror(SPARKLINE(AJ20/AI20,{""charttype"",""bar"";""max"",1;""color1"",""#c9e4b2""}))"),"")
C21: FALSE | D21: FALSE | E21: FALSE | F21: FALSE | G21: FALSE | H21: FALSE | I21: FALSE | J21: FALSE | K21: FALSE | L21: FALSE | M21: FALSE | N21: FALSE | O21: FALSE | P21: FALSE | Q21: FALSE | R21: FALSE | S21: FALSE | T21: FALSE | U21: FALSE | V21: FALSE | W21: FALSE | X21: FALSE | Y21: FALSE | Z21: FALSE | AA21: FALSE | AB21: FALSE | AC21: FALSE | AD21: FALSE | AE21: FALSE | AF21: FALSE | AG21: FALSE | AJ21: 0 | AK21: =IFERROR(__xludf.DUMMYFUNCTION("iferror(SPARKLINE(AJ21/AI21,{""charttype"",""bar"";""max"",1;""color1"",""#c9e4b2""}))"),"")
B23: Progres % | C23: =COUNTIF(C10:C21, TRUE)/COUNTA(C10:C21) -> 0 | D23: =COUNTIF(D10:D21, TRUE)/COUNTA(D10:D21) -> 0 | E23: =COUNTIF(E10:E21, TRUE)/COUNTA(E10:E21) -> 0 | F23: =COUNTIF(F10:F21, TRUE)/COUNTA(F10:F21) -> 0 | G23: =COUNTIF(G10:G21, TRUE)/COUNTA(G10:G21) -> 0 | H23: =COUNTIF(H10:H21, TRUE)/COUNTA(H10:H21) -> 0 | I23: =COUNTIF(I10:I21, TRUE)/COUNTA(I10:I21) -> 0 | J23: =COUNTIF(J10:J21, TRUE)/COUNTA(J10:J21) -> 0 | ... AG23: =COUNTIF(AG10:AG21, TRUE)/COUNTA(AG10:AG21) -> 0
B24: To'ldirilgan | C24: =COUNTIF(C10:C21, true) -> 0 | D24: =COUNTIF(D10:D21, true) -> 0 | E24: =COUNTIF(E10:E21, true) -> 0 | F24: =COUNTIF(F10:F21, true) -> 0 | G24: =COUNTIF(G10:G21, true) -> 0 | H24: =COUNTIF(H10:H21, true) -> 0 | I24: =COUNTIF(I10:I21, true) -> 0 | J24: =COUNTIF(J10:J21, true) -> 0 | ... AG24: =COUNTIF(AG10:AG21, true) -> 0
B25: To'ldirilmagan | C25: =COUNTIF(C10:C21, false) -> 12 | D25: =COUNTIF(D10:D21, false) -> 12 | E25: =COUNTIF(E10:E21, false) -> 12 | F25: =COUNTIF(F10:F21, false) -> 12 | G25: =COUNTIF(G10:G21, false) -> 12 | H25: =COUNTIF(H10:H21, false) -> 12 | I25: =COUNTIF(I10:I21, false) -> 12 | J25: =COUNTIF(J10:J21, false) -> 12 | ... AG25: =COUNTIF(AG10:AG21, false) -> 12
B36: Kundalik holat | AI36: O'rtacha qiymat
B37: Kayfiyat | AI37: =iferror(Average(C37:AG37), "")
B38: Energiya | AI38: =iferror(Average(C38:AG38), "")
B39: Motivatsiya | AI39: =iferror(Average(C39:AG39), "")
B42: Haftalik | C42: Hafta 1 | J42: Hafta 2 | Q42: Hafta 3 | X42: Hafta 4
I43: FALSE | P43: FALSE | W43: FALSE | AD43: FALSE
I44: FALSE | P44: FALSE | W44: FALSE | AD44: FALSE | AG44: January
I45: FALSE | P45: FALSE | W45: FALSE | AD45: FALSE | AG45: 5
I46: FALSE | P46: FALSE | W46: FALSE | AD46: FALSE
I47: FALSE | P47: FALSE | W47: FALSE | AD47: FALSE
B49: Haftalik fikrlar
B54: Oylik | C54: Ushbu oy maqsadlari
P55: FALSE
P56: FALSE
P57: FALSE
P58: FALSE
P59: FALSE
B62: =COUNTIF($I$43:$I$47, true) -> 0 | C62: {=$C$43:$H$47} | I62: {=COUNTA(UNIQUE($C$62:$C$140))} -> 0 | J62: =sum($B$62,$B$78,$B$110,$B$126) -> 0 | K62: =sum(COUNTA($I$43:$I$47),COUNTA($P$43:$P$47),COUNTA($W$43:$W$47),COUNTA($AD$43:$AD$47),COUNTA($P$55:$P$59)) -> 25
B78: =COUNTIF($P$43:$P$47, true) -> 0 | C78: {=$J$43:$O$47}
B94: =COUNTIF($W$43:$W$47, true) -> 0 | C94: {=$Q$43:$V$47}
...

Sheet Iyun
B3: Iyun | I3: Odatlar soni | O3: Bajarilgan odatlar soni | V3: Oylik Progres | AB3: Progres %
I4: =SUM(countA($B$10:$B$21),$I$62) -> 0 | O4: =SUM(COUNTIF($C$10:$AG$21, true),$J$62) -> 0 | V4: =IFERROR(__xludf.DUMMYFUNCTION("iferror(SPARKLINE($AB$4:$AF$4,{""charttype"",""bar"";""max"",1;""color1"",""#c9e4b2""}))"),"") | AB4: =$O$4/SUM(COUNTA($C$10:$AG$21),$K$62) -> 0
B7: Kundalik vazifalar | C7: Hafta 1 | J7: Hafta 2 | Q7: Hafta 3 | X7: Hafta 4 | AI7: Analiz | AK7: Progres
C8: =weekday(date(Dashboard!$Q$3,$AG$45,C9),1) -> 1 | D8: =weekday(date(Dashboard!$Q$3,$AG$45,D9),1) -> 2 | E8: =weekday(date(Dashboard!$Q$3,$AG$45,E9),1) -> 3 | F8: =weekday(date(Dashboard!$Q$3,$AG$45,F9),1) -> 4 | G8: =weekday(date(Dashboard!$Q$3,$AG$45,G9),1) -> 5 | H8: =weekday(date(Dashboard!$Q$3,$AG$45,H9),1) -> 6 | I8: =weekday(date(Dashboard!$Q$3,$AG$45,I9),1) -> 7 | J8: =weekday(date(Dashboard!$Q$3,$AG$45,J9),1) -> 1 | ... AG8: =weekday(date(Dashboard!$Q$3,$AG$45,AG9),1) -> 3
B9: =TODAY() -> 46025 | C9: 1 | D9: 2 | E9: 3 | F9: 4 | G9: 5 | H9: 6 | I9: 7 | J9: 8 | K9: 9 | L9: 10 | M9: 11 | N9: 12 | O9: 13 | P9: 14 | Q9: 15 | R9: 16 | S9: 17 | T9: 18 | U9: 19 | V9: 20 | W9: 21 | X9: 22 | Y9: 23 | Z9: 24 | AA9: 25 | AB9: 26 | AC9: 27 | AD9: 28 | AE9: 29 | AF9: 30 | AG9: 31 | AI9: Maqsad | AJ9: Jami
C10: FALSE | D10: FALSE | E10: FALSE | F10: FALSE | G10: FALSE | H10: FALSE | I10: FALSE | J10: FALSE | K10: FALSE | L10: FALSE | M10: FALSE | N10: FALSE | O10: FALSE | P10: FALSE | Q10: FALSE | R10: FALSE | S10: FALSE | T10: FALSE | U10: FALSE | V10: FALSE | W10: FALSE | X10: FALSE | Y10: FALSE | Z10: FALSE | AA10: FALSE | AB10: FALSE | AC10: FALSE | AD10: FALSE | AE10: FALSE | AF10: FALSE | AG10: FALSE | AJ10: {=MMULT(N($C$10:$AG$21), TRANSPOSE(COLUMN($C$10:$AG$21)^0))} -> 0 | AK10: =IFERROR(__xludf.DUMMYFUNCTION("iferror(SPARKLINE(AJ10/AI10,{""charttype"",""bar"";""max"",1;""color1"",""#c9e4b2""}))"),"")
C11: FALSE | D11: FALSE | E11: FALSE | F11: FALSE | G11: FALSE | H11: FALSE | I11: FALSE | J11: FALSE | K11: FALSE | L11: FALSE | M11: FALSE | N11: FALSE | O11: FALSE | P11: FALSE | Q11: FALSE | R11: FALSE | S11: FALSE | T11: FALSE | U11: FALSE | V11: FALSE | W11: FALSE | X11: FALSE | Y11: FALSE | Z11: FALSE | AA11: FALSE | AB11: FALSE | AC11: FALSE | AD11: FALSE | AE11: FALSE | AF11: FALSE | AG11: FALSE | AJ11: 0 | AK11: =IFERROR(__xludf.DUMMYFUNCTION("iferror(SPARKLINE(AJ11/AI11,{""charttype"",""bar"";""max"",1;""color1"",""#c9e4b2""}))"),"")
C12: FALSE | D12: FALSE | E12: FALSE | F12: FALSE | G12: FALSE | H12: FALSE | I12: FALSE | J12: FALSE | K12: FALSE | L12: FALSE | M12: FALSE | N12: FALSE | O12: FALSE | P12: FALSE | Q12: FALSE | R12: FALSE | S12: FALSE | T12: FALSE | U12: FALSE | V12: FALSE | W12: FALSE | X12: FALSE | Y12: FALSE | Z12: FALSE | AA12: FALSE | AB12: FALSE | AC12: FALSE | AD12: FALSE | AE12: FALSE | AF12: FALSE | AG12: FALSE | AJ12: 0 | AK12: =IFERROR(__xludf.DUMMYFUNCTION("iferror(SPARKLINE(AJ12/AI12,{""charttype"",""bar"";""max"",1;""color1"",""#c9e4b2""}))"),"")
C13: FALSE | D13: FALSE | E13: FALSE | F13: FALSE | G13: FALSE | H13: FALSE | I13: FALSE | J13: FALSE | K13: FALSE | L13: FALSE | M13: FALSE | N13: FALSE | O13: FALSE | P13: FALSE | Q13: FALSE | R13: FALSE | S13: FALSE | T13: FALSE | U13: FALSE | V13: FALSE | W13: FALSE | X13: FALSE | Y13: FALSE | Z13: FALSE | AA13: FALSE | AB13: FALSE | AC13: FALSE | AD13: FALSE | AE13: FALSE | AF13: FALSE | AG13: FALSE | AJ13: 0 | AK13: =IFERROR(__xludf.DUMMYFUNCTION("iferror(SPARKLINE(AJ13/AI13,{""charttype"",""bar"";""max"",1;""color1"",""#c9e4b2""}))"),"")
